[rank: 0] Seed set to 42
/work/cvcs_2023_group23/AIB/AIB_env/lib/python3.9/site-packages/torchvision/models/_utils.py:208: UserWarning: The parameter 'pretrained' is deprecated since 0.13 and will be removed in 0.15, please use 'weights' instead.
  warnings.warn(
/work/cvcs_2023_group23/AIB/AIB_env/lib/python3.9/site-packages/torchvision/models/_utils.py:223: UserWarning: Arguments other than a weight enum or `None` for 'weights' are deprecated since 0.13 and will be removed in 0.15. The current behavior is equivalent to passing `weights=ResNet18_Weights.IMAGENET1K_V1`. You can also use `weights=ResNet18_Weights.DEFAULT` to get the most up-to-date weights.
  warnings.warn(msg)
Using 16bit Automatic Mixed Precision (AMP)
GPU available: True (cuda), used: True
TPU available: False, using: 0 TPU cores
IPU available: False, using: 0 IPUs
HPU available: False, using: 0 HPUs
/work/cvcs_2023_group23/AIB/AIB_env/lib/python3.9/site-packages/pytorch_lightning/trainer/configuration_validator.py:72: You passed in a `val_dataloader` but have no `validation_step`. Skipping val loop.
[rank: 0] Seed set to 42
Initializing distributed: GLOBAL_RANK: 0, MEMBER: 1/4
Traceback (most recent call last):
  File "/work/cvcs_2023_group23/AIB/train_pl.py", line 112, in <module>
    main()
  File "/work/cvcs_2023_group23/AIB/train_pl.py", line 109, in main
    trainer.fit(model, data_module)
  File "/work/cvcs_2023_group23/AIB/AIB_env/lib/python3.9/site-packages/pytorch_lightning/trainer/trainer.py", line 545, in fit
    call._call_and_handle_interrupt(
  File "/work/cvcs_2023_group23/AIB/AIB_env/lib/python3.9/site-packages/pytorch_lightning/trainer/call.py", line 43, in _call_and_handle_interrupt
    return trainer.strategy.launcher.launch(trainer_fn, *args, trainer=trainer, **kwargs)
  File "/work/cvcs_2023_group23/AIB/AIB_env/lib/python3.9/site-packages/pytorch_lightning/strategies/launchers/subprocess_script.py", line 102, in launch
    return function(*args, **kwargs)
  File "/work/cvcs_2023_group23/AIB/AIB_env/lib/python3.9/site-packages/pytorch_lightning/trainer/trainer.py", line 581, in _fit_impl
    self._run(model, ckpt_path=ckpt_path)
  File "/work/cvcs_2023_group23/AIB/AIB_env/lib/python3.9/site-packages/pytorch_lightning/trainer/trainer.py", line 948, in _run
    self.strategy.setup_environment()
  File "/work/cvcs_2023_group23/AIB/AIB_env/lib/python3.9/site-packages/pytorch_lightning/strategies/ddp.py", line 146, in setup_environment
    self.setup_distributed()
  File "/work/cvcs_2023_group23/AIB/AIB_env/lib/python3.9/site-packages/pytorch_lightning/strategies/ddp.py", line 197, in setup_distributed
    _init_dist_connection(self.cluster_environment, self._process_group_backend, timeout=self._timeout)
  File "/work/cvcs_2023_group23/AIB/AIB_env/lib/python3.9/site-packages/lightning_fabric/utilities/distributed.py", line 290, in _init_dist_connection
    torch.distributed.init_process_group(torch_distributed_backend, rank=global_rank, world_size=world_size, **kwargs)
  File "/work/cvcs_2023_group23/AIB/AIB_env/lib/python3.9/site-packages/torch/distributed/distributed_c10d.py", line 627, in init_process_group
    _store_based_barrier(rank, store, timeout)
  File "/work/cvcs_2023_group23/AIB/AIB_env/lib/python3.9/site-packages/torch/distributed/distributed_c10d.py", line 255, in _store_based_barrier
    raise RuntimeError(
RuntimeError: Timed out initializing process group in store based barrier on rank: 0, for key: store_based_barrier_key:1 (world_size=4, worker_count=1, timeout=0:30:00)
[rank: 0] Seed set to 42
Traceback (most recent call last):
  File "/work/cvcs_2023_group23/AIB/eval_pl.py", line 64, in <module>
    main()
  File "/work/cvcs_2023_group23/AIB/eval_pl.py", line 38, in main
    model = SimCLRModule.load_from_checkpoint(checkpoint_path="checkpoints/parallel/last.ckpt")
  File "/work/cvcs_2023_group23/AIB/AIB_env/lib/python3.9/site-packages/pytorch_lightning/core/module.py", line 1552, in load_from_checkpoint
    loaded = _load_from_checkpoint(
  File "/work/cvcs_2023_group23/AIB/AIB_env/lib/python3.9/site-packages/pytorch_lightning/core/saving.py", line 61, in _load_from_checkpoint
    checkpoint = pl_load(checkpoint_path, map_location=map_location)
  File "/work/cvcs_2023_group23/AIB/AIB_env/lib/python3.9/site-packages/lightning_fabric/utilities/cloud_io.py", line 54, in _load
    with fs.open(path_or_url, "rb") as f:
  File "/work/cvcs_2023_group23/AIB/AIB_env/lib/python3.9/site-packages/fsspec/spec.py", line 1293, in open
    f = self._open(
  File "/work/cvcs_2023_group23/AIB/AIB_env/lib/python3.9/site-packages/fsspec/implementations/local.py", line 184, in _open
    return LocalFileOpener(path, mode, fs=self, **kwargs)
  File "/work/cvcs_2023_group23/AIB/AIB_env/lib/python3.9/site-packages/fsspec/implementations/local.py", line 306, in __init__
    self._open()
  File "/work/cvcs_2023_group23/AIB/AIB_env/lib/python3.9/site-packages/fsspec/implementations/local.py", line 311, in _open
    self.f = open(self.path, mode=self.mode)
FileNotFoundError: [Errno 2] No such file or directory: '/work/cvcs_2023_group23/AIB/checkpoints/parallel/last.ckpt'
